<?xml version="1.0" encoding="utf-8"?>
<!-- This URDF was automatically created by SolidWorks to URDF Exporter! Originally created by Stephen Brawner (brawner@gmail.com) 
     Commit Version: 1.6.0-4-g7f85cfe  Build Version: 1.6.7995.38578
     For more information, please see http://wiki.ros.org/sw_urdf_exporter -->
<robot
  name="four_links">
  <link
    name="base_link">
    <inertial>
      <origin
        xyz="-0.0420417072243827 -0.0743722309975965 -0.0245209736544894"
        rpy="0 0 0" />
      <mass
        value="0.0209510308536538" />
      <inertia
        ixx="4.31058987194356E-07"
        ixy="9.00920390220769E-22"
        ixz="1.6265494408689E-22"
        iyy="5.33666050979322E-05"
        iyz="3.4274231660628E-24"
        izz="5.34484802375657E-05" />
    </inertial>
    <visual>
      <origin
        xyz="0 0 0"
        rpy="0 0 0" />
      <geometry>
        <mesh
          filename="package://four_links/meshes/base_link.STL" />
      </geometry>
      <material
        name="">
        <color
          rgba="1 1 1 1" />
      </material>
    </visual>
    <collision>
      <origin
        xyz="0 0 0"
        rpy="0 0 0" />
      <geometry>
        <mesh
          filename="package://four_links/meshes/base_link.STL" />
      </geometry>
    </collision>
  </link>
  <link
    name="linkAB">
    <inertial>
      <origin
        xyz="0.0371817038425088 -6.08402217494586E-14 -0.005"
        rpy="0 0 0" />
      <mass
        value="0.00950214387592874" />
      <inertia
        ixx="1.97084106558777E-07"
        ixy="-2.59238403974119E-21"
        ixz="-7.40987074598825E-23"
        iyy="5.19422383682696E-06"
        iyz="-6.26387574287629E-24"
        izz="5.23293887878693E-06" />
    </inertial>
    <visual>
      <origin
        xyz="0 0 0"
        rpy="0 0 0" />
      <geometry>
        <mesh
          filename="package://four_links/meshes/linkAB.STL" />
      </geometry>
      <material
        name="">
        <color
          rgba="1 1 1 1" />
      </material>
    </visual>
    <collision>
      <origin
        xyz="0 0 0"
        rpy="0 0 0" />
      <geometry>
        <mesh
          filename="package://four_links/meshes/linkAB.STL" />
      </geometry>
    </collision>
  </link>
  <joint
    name="jointA"
    type="continuous">
    <origin
      xyz="-0.126714490675986 0.0295209736544894 -0.0743722309975965"
      rpy="1.5707963267949 -1.42221124002695 0" />
    <parent
      link="base_link" />
    <child
      link="linkAB" />
    <axis
      xyz="0 0 1" />
  </joint>
  <link
    name="linkBC">
    <inertial>
      <origin
        xyz="0.0544311472852489 0.00364847640014895 -0.00500000000448934"
        rpy="0 0 0" />
      <mass
        value="0.0180946249077626" />
      <inertia
        ixx="1.35905209390565E-06"
        ixy="1.7357626470457E-06"
        ixz="-1.42991788926848E-22"
        iyy="2.39956392272529E-05"
        iyz="4.56105317644272E-23"
        izz="2.50531142393625E-05" />
    </inertial>
    <visual>
      <origin
        xyz="0 0 0"
        rpy="0 0 0" />
      <geometry>
        <mesh
          filename="package://four_links/meshes/linkBC.STL" />
      </geometry>
      <material
        name="">
        <color
          rgba="1 1 1 1" />
      </material>
    </visual>
    <collision>
      <origin
        xyz="0 0 0"
        rpy="0 0 0" />
      <geometry>
        <mesh
          filename="package://four_links/meshes/linkBC.STL" />
      </geometry>
    </collision>
  </link>
  <joint
    name="jointB"
    type="continuous">
    <origin
      xyz="0.074166528159762 0.000154719377460921 -0.00999999999551065"
      rpy="0 0 -0.982349251785507" />
    <parent
      link="linkAB" />
    <child
      link="linkBC" />
    <axis
      xyz="0 0 1" />
  </joint>
  <link
    name="linkCD">
    <inertial>
      <origin
        xyz="-0.0678253502735387 -3.00037772404949E-14 -0.005"
        rpy="0 0 0" />
      <mass
        value="0.0167330198618603" />
      <inertia
        ixx="3.44857715381249E-07"
        ixy="6.81596824743695E-21"
        ixz="-8.50419918939852E-24"
        iyy="2.73613018527324E-05"
        iyz="9.68938210760468E-23"
        izz="2.74272759037493E-05" />
    </inertial>
    <visual>
      <origin
        xyz="0 0 0"
        rpy="0 0 0" />
      <geometry>
        <mesh
          filename="package://four_links/meshes/linkCD.STL" />
      </geometry>
      <material
        name="">
        <color
          rgba="1 1 1 1" />
      </material>
    </visual>
    <collision>
      <origin
        xyz="0 0 0"
        rpy="0 0 0" />
      <geometry>
        <mesh
          filename="package://four_links/meshes/linkCD.STL" />
      </geometry>
    </collision>
  </link>
  <joint
    name="jointD"
    type="continuous">
    <origin
      xyz="0.0432855093240141 0.0295209736544894 -0.0743722309975965"
      rpy="1.5707963267949 1.18883685572557 0" />
    <parent
      link="base_link" />
    <child
      link="linkCD" />
    <axis
      xyz="0 0 1" />
  </joint>
</robot>